<?xml version="1.0" encoding="utf-8"?>
<!-- This URDF was automatically created by SolidWorks to URDF Exporter! Originally created by Stephen Brawner (brawner@gmail.com) 
     Commit Version: 1.6.0-4-g7f85cfe  Build Version: 1.6.7995.38578
     For more information, please see http://wiki.ros.org/sw_urdf_exporter -->
<robot
  name="URDF_XG_Robot_Arm_Step_Urdf_V1">
  <link
    name="base_link">
    <inertial>
      <origin
        xyz="-6.62271790898677E-05 -0.000162301184482969 0.0589260607237122"
        rpy="0 0 0" />
      <mass
        value="0.553880194517112" />
      <inertia
        ixx="0.00125395744532095"
        ixy="6.30504993363177E-07"
        ixz="4.37302567472786E-06"
        iyy="0.00125390287854359"
        iyz="-4.01972122790883E-06"
        izz="0.000721320676009685" />
    </inertial>
    <visual>
      <origin
        xyz="0 0 0"
        rpy="0 0 0" />
      <geometry>
        <mesh
          filename="package://URDF_XG_Robot_Arm_Step_Urdf_V1/meshes/base_link.STL" />
      </geometry>
      <material
        name="">
        <color
          rgba="0.752941176470588 0.752941176470588 0.752941176470588 1" />
      </material>
    </visual>
    <collision>
      <origin
        xyz="0 0 0"
        rpy="0 0 0" />
      <geometry>
        <mesh
          filename="package://URDF_XG_Robot_Arm_Step_Urdf_V1/meshes/base_link.STL" />
      </geometry>
    </collision>
  </link>
  <link
    name="link1">
    <inertial>
      <origin
        xyz="0.0243405579392273 0.000159015425943267 0.00639309218537437"
        rpy="0 0 0" />
      <mass
        value="0.0608469523040024" />
      <inertia
        ixx="2.56788832154839E-05"
        ixy="1.15776886055255E-07"
        ixz="-1.10292460962293E-05"
        iyy="3.70074391646153E-05"
        iyz="-3.2599674177669E-08"
        izz="3.87763473470932E-05" />
    </inertial>
    <visual>
      <origin
        xyz="0 0 0"
        rpy="0 0 0" />
      <geometry>
        <mesh
          filename="package://URDF_XG_Robot_Arm_Step_Urdf_V1/meshes/link1.STL" />
      </geometry>
      <material
        name="">
        <color
          rgba="0.752941176470588 0.752941176470588 0.752941176470588 1" />
      </material>
    </visual>
    <collision>
      <origin
        xyz="0 0 0"
        rpy="0 0 0" />
      <geometry>
        <mesh
          filename="package://URDF_XG_Robot_Arm_Step_Urdf_V1/meshes/link1.STL" />
      </geometry>
    </collision>
  </link>
  <joint
    name="joint1"
    type="continuous">
    <origin
      xyz="0 0 0.1419"
      rpy="0 0 0" />
    <parent
      link="base_link" />
    <child
      link="link1" />
    <axis
      xyz="0 0 1" />
  </joint>
  <link
    name="link2">
    <inertial>
      <origin
        xyz="-0.100016791988138 -0.00010706635232322 -0.0382835162524506"
        rpy="0 0 0" />
      <mass
        value="0.433546101826059" />
      <inertia
        ixx="0.000140434169716263"
        ixy="-5.94210696535013E-08"
        ixz="-1.1298489980335E-06"
        iyy="0.00105045835658707"
        iyz="-4.8684776465153E-08"
        izz="0.00104172634579533" />
    </inertial>
    <visual>
      <origin
        xyz="0 0 0"
        rpy="0 0 0" />
      <geometry>
        <mesh
          filename="package://URDF_XG_Robot_Arm_Step_Urdf_V1/meshes/link2.STL" />
      </geometry>
      <material
        name="">
        <color
          rgba="0.752941176470588 0.752941176470588 0.752941176470588 1" />
      </material>
    </visual>
    <collision>
      <origin
        xyz="0 0 0"
        rpy="0 0 0" />
      <geometry>
        <mesh
          filename="package://URDF_XG_Robot_Arm_Step_Urdf_V1/meshes/link2.STL" />
      </geometry>
    </collision>
  </link>
  <joint
    name="joint2"
    type="revolute">
    <origin
      xyz="0.0275 0 0.0241"
      rpy="0 1.5708 0" />
    <parent
      link="link1" />
    <child
      link="link2" />
    <axis
      xyz="0 0 1" />
    <limit
      lower="-1.5708"
      upper="1.5708"
      effort="0"
      velocity="0" />
  </joint>
  <link
    name="link3">
    <inertial>
      <origin
        xyz="0.0479933927894934 -0.0413167220936428 -0.0165548245293061"
        rpy="0 0 0" />
      <mass
        value="0.163443679464034" />
      <inertia
        ixx="7.61011370618006E-05"
        ixy="2.70605976616821E-05"
        ixz="4.05496538702261E-05"
        iyy="0.000132142857400073"
        iyz="-1.53294424817123E-05"
        izz="0.000133520429120662" />
    </inertial>
    <visual>
      <origin
        xyz="0 0 0"
        rpy="0 0 0" />
      <geometry>
        <mesh
          filename="package://URDF_XG_Robot_Arm_Step_Urdf_V1/meshes/link3.STL" />
      </geometry>
      <material
        name="">
        <color
          rgba="0.752941176470588 0.752941176470588 0.752941176470588 1" />
      </material>
    </visual>
    <collision>
      <origin
        xyz="0 0 0"
        rpy="0 0 0" />
      <geometry>
        <mesh
          filename="package://URDF_XG_Robot_Arm_Step_Urdf_V1/meshes/link3.STL" />
      </geometry>
    </collision>
  </link>
  <joint
    name="joint3"
    type="revolute">
    <origin
      xyz="-0.2 0 0"
      rpy="0 0 0" />
    <parent
      link="link2" />
    <child
      link="link3" />
    <axis
      xyz="0 0 1" />
    <limit
      lower="-1.5708"
      upper="0"
      effort="0"
      velocity="0" />
  </joint>
  <link
    name="link4">
    <inertial>
      <origin
        xyz="-0.00682767078892278 2.81608060713895E-05 -0.0585544918262343"
        rpy="0 0 0" />
      <mass
        value="0.178465854690518" />
      <inertia
        ixx="0.000111293192127187"
        ixy="1.56493108952721E-07"
        ixz="-4.12005755743812E-07"
        iyy="0.000105420709556455"
        iyz="1.1762751671768E-07"
        izz="4.42311174651251E-05" />
    </inertial>
    <visual>
      <origin
        xyz="0 0 0"
        rpy="0 0 0" />
      <geometry>
        <mesh
          filename="package://URDF_XG_Robot_Arm_Step_Urdf_V1/meshes/link4.STL" />
      </geometry>
      <material
        name="">
        <color
          rgba="0.752941176470588 0.752941176470588 0.752941176470588 1" />
      </material>
    </visual>
    <collision>
      <origin
        xyz="0 0 0"
        rpy="0 0 0" />
      <geometry>
        <mesh
          filename="package://URDF_XG_Robot_Arm_Step_Urdf_V1/meshes/link4.STL" />
      </geometry>
    </collision>
  </link>
  <joint
    name="joint4"
    type="continuous">
    <origin
      xyz="0.096 -0.047631 -0.0275"
      rpy="0 -1.5708 0" />
    <parent
      link="link3" />
    <child
      link="link4" />
    <axis
      xyz="0 0 1" />
  </joint>
  <link
    name="link5">
    <inertial>
      <origin
        xyz="-0.000156431818421676 0.0617917966301192 0.015474716621298"
        rpy="0 0 0" />
      <mass
        value="0.15793222447205" />
      <inertia
        ixx="0.000135933655838788"
        ixy="-6.33132038696916E-08"
        ixz="-8.3886144493004E-09"
        iyy="5.60082572905535E-05"
        iyz="-3.96647905066164E-05"
        izz="0.000121456700565665" />
    </inertial>
    <visual>
      <origin
        xyz="0 0 0"
        rpy="0 0 0" />
      <geometry>
        <mesh
          filename="package://URDF_XG_Robot_Arm_Step_Urdf_V1/meshes/link5.STL" />
      </geometry>
      <material
        name="">
        <color
          rgba="0.752941176470588 0.752941176470588 0.752941176470588 1" />
      </material>
    </visual>
    <collision>
      <origin
        xyz="0 0 0"
        rpy="0 0 0" />
      <geometry>
        <mesh
          filename="package://URDF_XG_Robot_Arm_Step_Urdf_V1/meshes/link5.STL" />
      </geometry>
    </collision>
  </link>
  <joint
    name="joint5"
    type="revolute">
    <origin
      xyz="0.0255 0 -0.0885"
      rpy="3.1416 1.5708 0" />
    <parent
      link="link4" />
    <child
      link="link5" />
    <axis
      xyz="0 0 1" />
    <limit
      lower="-3.1416"
      upper="0"
      effort="0"
      velocity="0" />
  </joint>
  <link
    name="ee_link">
    <inertial>
      <origin
        xyz="-5.5511E-17 6.0774E-17 0.0078931"
        rpy="0 0 0" />
      <mass
        value="0.0088164" />
      <inertia
        ixx="6.5293E-07"
        ixy="-7.2762E-23"
        ixz="-1.8939E-21"
        iyy="6.5293E-07"
        iyz="2.5171E-21"
        izz="9.3068E-07" />
    </inertial>
    <visual>
      <origin
        xyz="0 0 0"
        rpy="0 0 0" />
      <geometry>
        <mesh
          filename="package://URDF_XG_Robot_Arm_Step_Urdf_V1/meshes/ee_link.STL" />
      </geometry>
      <material
        name="">
        <color
          rgba="0.75294 0.75294 0.75294 1" />
      </material>
    </visual>
    <collision>
      <origin
        xyz="0 0 0"
        rpy="0 0 0" />
      <geometry>
        <mesh
          filename="package://URDF_XG_Robot_Arm_Step_Urdf_V1/meshes/ee_link.STL" />
      </geometry>
    </collision>
  </link>
  <joint
    name="joint6"
    type="continuous">
    <origin
      xyz="0 0.109 0.0255"
      rpy="-1.5708 0 0" />
    <parent
      link="link5" />
    <child
      link="ee_link" />
    <axis
      xyz="0 0 1" />
  </joint>
</robot>